#VRML_SIM R2021a utf8
WorldInfo {
  coordinateSystem "NUE"
}
Viewpoint {
  orientation -0.9969529774083993 0.06951401520832702 0.0353915600976291 0.221907617691719
  position -0.005235388243889777 0.731336165532856 1.5224322964920505
}
TexturedBackground {
}
Robot {
  translation 0 0.25 0
  children [
    DEF BODY Shape {
      appearance PBRAppearance {
        baseColor 0.666667 0 0.498039
      }
      geometry Box {
        size 0.5 0.3 0.5
      }
    }
    HingeJoint {
      endPoint Solid {
        children [
          Solid {
            translation 0.1 0 0.25
            rotation 0 0.7071067811865475 0.7071067811865475 3.1299194858799644
            children [
              DEF WHEEL Shape {
                appearance PBRAppearance {
                }
                geometry Cylinder {
                  height 0.1
                  radius 0.05
                }
              }
            ]
            boundingObject USE WHEEL
            physics Physics {
            }
          }
        ]
        physics Physics {
        }
      }
    }
    HingeJoint {
    }
    HingeJoint {
    }
    HingeJoint {
    }
  ]
  boundingObject USE BODY
  physics Physics {
  }
}
TexturedBackgroundLight {
}
