#VRML_SIM R2021a utf8
WorldInfo {
  coordinateSystem "NUE"
}
Viewpoint {
  orientation 0.0015999773172463807 0.9295774253192566 0.3686234534174492 3.133140911610369
  position -0.010523644796044472 5.7035498753649705 -5.819365802894228
}
TexturedBackground {
}
Floor {
}
Robot {
  translation 0 0.1 0
  scale 2 2 2
  children [
    GPS {
    }
    DEF BODY Shape {
      appearance PBRAppearance {
        baseColor 0.666667 0 0.498039
      }
      geometry Box {
        size 0.1 0.05 0.2
      }
    }
    DistanceSensor {
      translation -0.03 0 0.1
      rotation 0 1 0 -2.094399693899575
      children [
        DEF sensor Shape {
          appearance PBRAppearance {
          }
          geometry Sphere {
            radius 0.01
          }
        }
      ]
      name "dsR"
      boundingObject USE sensor
      physics Physics {
      }
      lookupTable [
        0 0 0
        0.2 1000 0
      ]
    }
    DistanceSensor {
      translation -0.05 0 0
      rotation 0 1 0 -3.141592653589793
      children [
        DEF sensor Shape {
          appearance PBRAppearance {
          }
          geometry Sphere {
            radius 0.01
          }
        }
      ]
      name "dsSR"
      boundingObject USE sensor
      physics Physics {
      }
      lookupTable [
        0 0 0
        0.2 1000 0
      ]
    }
    DistanceSensor {
      translation 0.05 0 0
      children [
        DEF sensor Shape {
          appearance PBRAppearance {
          }
          geometry Sphere {
            radius 0.01
          }
        }
      ]
      name "dsSL"
      boundingObject USE sensor
      physics Physics {
      }
      lookupTable [
        0 0 0
        0.2 1000 0
      ]
    }
    DistanceSensor {
      translation 0.03 0 0.1
      rotation 0 1 0 -1.0472003061004251
      children [
        DEF sensor Shape {
          appearance PBRAppearance {
          }
          geometry Sphere {
            radius 0.01
          }
        }
      ]
      name "dsL"
      boundingObject USE sensor
      physics Physics {
      }
      lookupTable [
        0 0 0
        0.2 1000 0
      ]
    }
    DEF wheelLF HingeJoint {
      jointParameters HingeJointParameters {
        anchor 0.06 0 0.05
      }
      device [
        RotationalMotor {
          name "wheelLF"
        }
      ]
      endPoint Solid {
        translation 0.060004348487124215 1.6497732466144229e-06 0.049974956485942454
        rotation -0.1460470306680831 0.14430859776733038 0.9786957103428333 1.5933761199380534
        children [
          DEF wheel Shape {
            appearance PBRAppearance {
            }
            geometry Cylinder {
              height 0.02
              radius 0.04
            }
          }
        ]
        boundingObject USE wheel
        physics Physics {
        }
      }
    }
    DEF wheelLR HingeJoint {
      jointParameters HingeJointParameters {
        anchor 0.06 0 -0.05
      }
      device [
        RotationalMotor {
          name "wheelLR"
        }
      ]
      endPoint Solid {
        translation 0.060014830930629204 -7.230134244095258e-06 -0.04999725261319623
        rotation -0.14604610059895307 0.14430863555818674 0.9786958435607944 1.5933753937081439
        children [
          USE wheel
        ]
        name "solid(1)"
        boundingObject USE wheel
        physics Physics {
        }
      }
    }
    DEF wheelRF HingeJoint {
      jointParameters HingeJointParameters {
        anchor -0.06 0 0.05
      }
      device [
        RotationalMotor {
          name "wheelRF"
        }
      ]
      endPoint Solid {
        translation -0.06002626743024142 4.035359892664091e-05 0.050011911957033535
        rotation -0.16575598791266669 0.16480519019695597 0.9722984118855904 1.6008472245324463
        children [
          USE wheel
        ]
        name "solid(1)"
        boundingObject USE wheel
        physics DEF wheel_phy Physics {
          mass 0.1
        }
      }
    }
    DEF wheelRR HingeJoint {
      jointParameters HingeJointParameters {
        anchor -0.06 0 -0.05
      }
      device [
        RotationalMotor {
          name "wheelRR"
        }
      ]
      endPoint Solid {
        translation -0.059992578006273556 2.0904092974336402e-05 -0.05000537555973068
        rotation -0.16575614167977887 0.16480350132472793 0.9722986719349891 1.6008497858283024
        children [
          USE wheel
        ]
        name "solid(1)"
        boundingObject USE wheel
        physics Physics {
        }
      }
    }
  ]
  boundingObject USE BODY
  physics Physics {
    density -1
    mass 1
  }
  controller "robot"
}
Shelves {
  translation -2.3 0 0
}
TexturedBackgroundLight {
}
DEF WALL_1 Solid {
  translation 2.5 0.05 0
  scale 5 5 5
  children [
    DEF WALL_SHAPE Shape {
      appearance PBRAppearance {
        baseColor 0.12549 0.368627 0.729412
        roughness 1
        metalness 0
      }
      geometry Box {
        size 0.02 0.1 0.98
      }
    }
  ]
  boundingObject USE WALL_SHAPE
}
DEF WALL_2 Solid {
  translation -2.5 0.05 0
  scale 5 5 5
  children [
    DEF WALL_SHAPE Shape {
      appearance PBRAppearance {
        baseColor 0.12549 0.368627 0.729412
        roughness 1
        metalness 0
      }
      geometry Box {
        size 0.02 0.1 0.98
      }
    }
  ]
  name "solid(1)"
  boundingObject USE WALL_SHAPE
}
DEF WALL_3 Solid {
  translation 0 0.05 -2.5
  rotation 0 1 0 1.5708
  scale 5 5 5
  children [
    DEF WALL_SHAPE Shape {
      appearance PBRAppearance {
        baseColor 0.12549 0.368627 0.729412
        roughness 1
        metalness 0
      }
      geometry Box {
        size 0.02 0.1 0.98
      }
    }
  ]
  name "solid(2)"
  boundingObject USE WALL_SHAPE
}
DEF WALL_4 Solid {
  translation 0 0.05 2.5
  rotation 0 1 0 1.5708
  scale 5 5 5
  children [
    DEF WALL_SHAPE Shape {
      appearance PBRAppearance {
        baseColor 0.12549 0.368627 0.729412
        roughness 1
        metalness 0
      }
      geometry Box {
        size 0.02 0.1 0.98
      }
    }
  ]
  name "solid(3)"
  boundingObject USE WALL_SHAPE
}
